Workbook

Sheet EDT
A2: Matriz Estructura de descomposición de tareas EDT
I3: DICCIONARIO EDT
A4: Etapas | B4: DIAS | C4: HORAS POR ACTIVIDAD O ENTREGABLE | I4: ROL ACTOR | J4: NOMBRE ACTOR
A5: Fase de Planificación | B5: =SUM(B6:B9) -> 7 | C5: Jefe de Proyecto | D5: Analista Programador | E5: DBA | F5: QA | G5: Diseñador | I5: Jefe de Proyecto | J5: Juan Miranda
A6: Acta de Constitución de proyecto | B6: =SUM(C6:G6)/8 -> 2 | C6: 8 | D6: 8 | I6: Analista Programador | J6: Francisco Lobos
A7: Aprobación del Acta | B7: =SUM(C7:G7)/8 -> 0.5 | C7: 4 | I7: DBA | J7: Matias Pizarro
A8: Definición de requerimientos Generales | B8: =SUM(C8:G8)/8 -> 1.5 | C8: 8 | D8: 4 | I8: QA | J8: Francisco Gonzalez
A9: Organización del equipo | B9: =SUM(C9:G9)/8 -> 3 | C9: 8 | D9: 4 | E9: 4 | F9: 4 | G9: 4 | I9: Diseñador | J9: Enrique Sanchez
A10: Fase de Análisis y diseño | B10: =SUM(B11:B15) -> 14 | C10: Jefe de Proyecto | D10: Analista Programador | E10: DBA | F10: QA | G10: Diseñador
A11: Captura de requerimientos específicos | B11: =SUM(C11:G11)/8 -> 2.5 | C11: 12 | D11: 8
A12: Documento de casos de uso | B12: =SUM(C12:G12)/8 -> 1.5 | D12: 12
A13: Prototipos | B13: =SUM(C13:G13)/8 -> 4 | C13: 8 | G13: 24
A14: Propuesta ERS | B14: =SUM(C14:G14)/8 -> 2 | C14: 16
A15: Documento de arquitectura SW | B15: =SUM(C15:G15)/8 -> 4 | C15: 24 | D15: 8
A16: Fase de Desarrollo | B16: =B17+B21+B25+B29+B40+B44+B47+B51+B57 -> 39 | C16: Jefe de Proyecto | D16: Analista Programador | E16: DBA | F16: QA | G16: Diseñador
A17: Implementación ambiente de desarrollo | B17: =SUM(B18:B20) -> 4
A18: Implementación de ambiente de contenedores (Docker / Compose) | B18: =SUM(C18:G18)/8 -> 1 | D18: 8
A19: Configuración base del ecosistema frontend y componentes de UI | B19: =SUM(C19:G19)/8 -> 1 | D19: 8
A20: Creación de los scripts de tablas base de datos | B20: =SUM(C20:G20)/8 -> 2 | E20: 16
A21: Módulo Autenticación | B21: =SUM(B22:B24) -> 4
A22: Interfaz de autenticación | B22: =SUM(C22:G22)/8 -> 1 | D22: 4 | G22: 4
A23: Integración con Clerk | B23: =SUM(C23:G23)/8 -> 2 | D23: 16
A24: Implementación de persistencia local y manejo de estado offline | B24: =SUM(C24:G24)/8 -> 1 | D24: 8
A25: Módulo Notificaciones | B25: =SUM(B26:B28) -> 5
A26: Enviar notificaciones | B26: =SUM(C26:G26)/8 -> 1.5 | D26: 8 | G26: 4
A27: Enviar correos | B27: =SUM(C27:G27)/8 -> 1.5 | D27: 8 | G27: 4
A28: Integrar API de Resend | B28: =SUM(C28:G28)/8 -> 2 | D28: 16
A29: Módulo Administración | B29: =SUM(B30:B39) -> 10
A30: Gestionar Usuarios | B30: =SUM(C30:G30)/8 -> 1 | D30: 4 | G30: 4
A31: Gestionar Roles | B31: =SUM(C31:G31)/8 -> 1 | D31: 4 | G31: 4
A32: Gestionar Clínica | B32: =SUM(C32:G32)/8 -> 1 | D32: 4 | G32: 4
A33: Gestionar Colaboradores | B33: =SUM(C33:G33)/8 -> 1 | D33: 4 | G33: 4
A34: Gestionar Comunas y Sectores | B34: =SUM(C34:G34)/8 -> 1 | D34: 4 | G34: 4
A35: Gestionar Disponibilidad | B35: =SUM(C35:G35)/8 -> 1 | D35: 4 | G35: 4
A36: Gestionar Horarios | B36: =SUM(C36:G36)/8 -> 1 | D36: 4 | G36: 4
A37: Gestionar Servicios | B37: =SUM(C37:G37)/8 -> 1 | D37: 4 | G37: 4
A38: Gestionar Motivos de consulta | B38: =SUM(C38:G38)/8 -> 1 | D38: 4 | G38: 4
A39: Gestionar Especies y Razas | B39: =SUM(C39:G39)/8 -> 1 | D39: 4 | G39: 4
A40: Módulo Datos | B40: =SUM(B41:B43) -> 3
A41: Gestionar Tutor | B41: =SUM(C41:G41)/8 -> 1 | D41: 4 | G41: 4
...

Sheet Costos Fases
A2: SIGLA | B2: ROL | C2: NOMBRE | D2: VALOR HORA HH | E2: HORAS | F2: FASE PLANIFICACION | H2: COSTO POR HORA
A3: JP | B3: Jefe de Proyecto | C3: =I4 -> Juan Miranda | D3: =J4 -> 11904.762 | E3: =SUM(EDT!C6:C9) -> 28 | F3: =D3*E3 -> 333333.33 | H3: ROL | I3: NOMBRE | J3: COSTO x HORA | K3: Sueldo mes
A4: AP | B4: Analista Programador | C4: =I5 -> Francisco Lobos | D4: =J5 -> 7738.0952 | E4: =SUM(EDT!D6:D9) -> 16 | F4: =D4*E4 -> 123809.52 | H4: Jefe de Proyecto | I4: =EDT!J5 -> Juan Miranda | J4: =K4/168 -> 11904.762 | K4: 2000000
A5: DBA | B5: Desarrollador BD | C5: =I6 -> Matias Pizarro | D5: =J6 -> 9523.8095 | E5: =SUM(EDT!E6:E9) -> 4 | F5: =D5*E5 -> 38095.238 | H5: Analista Programador | I5: =EDT!J6 -> Francisco Lobos | J5: =K5/168 -> 7738.0952 | K5: 1300000
A6: QA | B6: Calidad Y Testing | C6: =I7 -> Francisco Gonzalez | D6: =J7 -> 6547.619 | E6: =SUM(EDT!F6:F9) -> 4 | F6: =D6*E6 -> 26190.476 | H6: Administrador BD | I6: =EDT!J7 -> Matias Pizarro | J6: =K6/168 -> 9523.8095 | K6: 1600000
A7: DI | B7: Diseñador | C7: =I8 -> Enrique Sanchez | D7: =J8 -> 5357.1429 | E7: =SUM(EDT!G6:G9) -> 4 | F7: =D7*E7 -> 21428.571 | H7: Calidad Y Testing | I7: =EDT!J8 -> Francisco Gonzalez | J7: =K7/168 -> 6547.619 | K7: 1100000
B8: TOTAL FASE PLANIFICACION | C8: =I9 | D8: =J9 | F8: =SUM(F3:F7) -> 542857.14 | H8: Diseñador | I8: =EDT!J9 -> Enrique Sanchez | J8: =K8/168 -> 5357.1429 | K8: 900000
A11: SIGLA | B11: ROL | C11: NOMBRE | D11: VALOR HORA HH | E11: HORAS | F11: FASE DISEÑO | H11: COSTO HH POR ROL
A12: JP | B12: Jefe de Proyecto | C12: =I4 -> Juan Miranda | D12: =J4 -> 11904.762 | E12: =SUM(EDT!C11:C15) -> 60 | F12: =D12*E12 -> 714285.71 | H12: Jefe de Proyecto | I12: =F3+F12+F21+F30+F39 -> 1380952.4
A13: AP | B13: Analista Programador | C13: =I5 -> Francisco Lobos | D13: =J5 -> 7738.0952 | E13: =SUM(EDT!D11:D15) -> 28 | F13: =D13*E13 -> 216666.67 | H13: Analista Programador | I13: =F4+F13+F22+F31+F40 -> 2042857.1
A14: DBA | B14: Desarrollador BD | C14: =I6 -> Matias Pizarro | D14: =J6 -> 9523.8095 | E14: =SUM(EDT!E11:E15) -> 0 | F14: =D14*E14 -> 0 | H14: Administrador BD | I14: =F5+F14+F23+F32+F41 -> 266666.67
A15: QA | B15: Calidad Y Testing | C15: =I7 -> Francisco Gonzalez | D15: =J7 -> 6547.619 | E15: =SUM(EDT!F11:F15) -> 0 | F15: =D15*E15 -> 0 | H15: Calidad Y Testing | I15: =F6+F15+F24+F33+F42 -> 445238.1
A16: DI | B16: Diseñador | C16: =I8 -> Enrique Sanchez | D16: =J8 -> 5357.1429 | E16: =SUM(EDT!G11:G15) -> 24 | F16: =D16*E16 -> 128571.43 | H16: Diseñador | I16: =F7+F16+F25+F34+F43 -> 707142.86
B17: TOTAL FASE DISEÑO | C17: =I9 | D17: =J9 | F17: =SUM(F12:F16) -> 1059523.8 | H17: TOTAL HH | I17: =SUM(I12:I16) -> 4842857.1
A20: SIGLA | B20: ROL | C20: NOMBRE | D20: VALOR HORA HH | E20: HORAS | F20: FASE DESARROLLO | H20: COSTO POR FASE
A21: JP | B21: Jefe de Proyecto | C21: =I4 -> Juan Miranda | D21: =J4 -> 11904.762 | E21: =SUM(EDT!C18:C58) -> 0 | F21: =D21*E21 -> 0 | H21: Fase de Planificación | I21: =F8 -> 542857.14
A22: AP | B22: Analista Programador | C22: =I5 -> Francisco Lobos | D22: =J5 -> 7738.0952 | E22: =SUM(EDT!D18:D58) -> 192 | F22: =D22*E22 -> 1485714.3 | H22: Fase de Análisis y Diseño | I22: =F17 -> 1059523.8
A23: DBA | B23: Desarrollador BD | C23: =I6 -> Matias Pizarro | D23: =J6 -> 9523.8095 | E23: =SUM(EDT!E18:E58) -> 16 | F23: =D23*E23 -> 152380.95 | H23: Fase de Desarrollo | I23: =F26 -> 2195238.1
A24: QA | B24: Calidad Y Testing | C24: =I7 -> Francisco Gonzalez | D24: =J7 -> 6547.619 | E24: =SUM(EDT!F18:F58) -> 0 | F24: =D24*E24 -> 0 | H24: Fase de QA | I24: =F35 -> 588095.24
A25: DI | B25: Diseñador | C25: =I8 -> Enrique Sanchez | D25: =J8 -> 5357.1429 | E25: =SUM(EDT!G18:G58) -> 104 | F25: =D25*E25 -> 557142.86 | H25: Fase de Implementación y Cierre | I25: =F44 -> 457142.86
B26: TOTAL FASE DESARROLLO | C26: =I9 | D26: =J9 | F26: =SUM(F21:F25) -> 2195238.1 | H26: TOTAL HH FASES | I26: =SUM(I21:I25) -> 4842857.1
A29: SIGLA | B29: ROL | C29: NOMBRE | D29: VALOR HORA HH | E29: HORAS | F29: FASE PRUEBAS QA | H29: Margen | I29: 0.6
A30: JP | B30: Jefe de Proyecto | C30: =I4 -> Juan Miranda | D30: =J4 -> 11904.762 | E30: =SUM(EDT!C60:C64) -> 8 | F30: =D30*E30 -> 95238.095 | H30: UTILIDAD | I30: =I26*I29 -> 2905714.3
A31: AP | B31: Analista Programador | C31: =I5 -> Francisco Lobos | D31: =J5 -> 7738.0952 | E31: =SUM(EDT!D60:D64) -> 8 | F31: =D31*E31 -> 61904.762 | H31: PRECIO FINAL | I31: =ROUND(I26+I30,-4) -> 7750000
A32: DBA | B32: Desarrollador BD | C32: =I6 -> Matias Pizarro | D32: =J6 -> 9523.8095 | E32: =SUM(EDT!E60:E64) -> 4 | F32: =D32*E32 -> 38095.238
A33: QA | B33: Calidad Y Testing | C33: =I7 -> Francisco Gonzalez | D33: =J7 -> 6547.619 | E33: =SUM(EDT!F60:F64) -> 60 | F33: =D33*E33 -> 392857.14
A34: DI | B34: Diseñador | C34: =I8 -> Enrique Sanchez | D34: =J8 -> 5357.1429 | E34: =SUM(EDT!G60:G64) -> 0 | F34: =D34*E34 -> 0
B35: TOTAL FASE PRUEBAS QA | D35: =J9 | F35: =SUM(F30:F34) -> 588095.24
A38: SIGLA | B38: ROL | C38: NOMBRE | D38: VALOR HORA HH | E38: HORAS | F38: FASE IMPLEMENTACION Y CIERRE
A39: JP | B39: Jefe de Proyecto | C39: =I4 -> Juan Miranda | D39: =J4 -> 11904.762 | E39: =SUM(EDT!C66:C69) -> 20 | F39: =D39*E39 -> 238095.24
A40: AP | B40: Analista Programador | C40: =I5 -> Francisco Lobos | D40: =J5 -> 7738.0952 | E40: =SUM(EDT!D66:D69) -> 20 | F40: =D40*E40 -> 154761.9
A41: DBA | B41: Desarrollador BD | C41: =I6 -> Matias Pizarro | D41: =J6 -> 9523.8095 | E41: =SUM(EDT!E66:E69) -> 4 | F41: =D41*E41 -> 38095.238
A42: QA | B42: Calidad Y Testing | C42: =I7 -> Francisco Gonzalez | D42: =J7 -> 6547.619 | E42: =SUM(EDT!F66:F69) -> 4 | F42: =D42*E42 -> 26190.476
A43: DI | B43: Diseñador | C43: =I8 -> Enrique Sanchez | D43: =J8 -> 5357.1429 | E43: =SUM(EDT!G66:G69) -> 0 | F43: =D43*E43 -> 0
B44: TOTAL FASE IMPLEMENTACION | D44: =J9 | F44: =SUM(F39:F43) -> 457142.86
